<?xml version="1.0"?>





<robot xmlns:xacro="http://www.ros.org/wiki/xacro" name="diffdrive">
    
    
    
    <xacro:include filename="gazebo.xacro" />
    <xacro:include filename="camera.xacro" />

    <material name="white">
        <color rgba="1 1 1 1" />
    </material>

    <material name="orange">
        <color rgba="1 0.3 0.1 1"/>
    </material>

    <material name="blue">
        <color rgba="0.2 0.2 1 1"/>
    </material>

    <material name="black">
        <color rgba="0 0 0 1"/>
    </material>
    <link name="base_link">
        
    </link>
    <joint name="chasis_joint" type="fixed">
        <parent link="base_link"/>
        <child link="chassis"/>
        <origin xyz="0.1 0 0"/>
    </joint>
   
    <link name="chassis">
        <inertial>
            <origin xyz="0.15 0 0.075" rpy="0.0 0.0 0.0"/>
            <mass value="0.5"/>
            <inertia ixx="0.00469" ixy="0.0" ixz="0.0"
                    iyy="0.00469" iyz="0.0"
                    izz="0.0075" />
        <origin xyz="0.15 0 0.075" rpy="0 0 0"/>
        </inertial>
        <visual name="">
            <origin xyz="0.15 0 0.075" rpy="0.0 0.0 0.0"/>
            <geometry>
                <box size="0.3 0.3 0.15"/>
            </geometry>
            <material name="blue">   
            </material>
        </visual>
        <collision>
            <origin xyz="0.15 0 0.075" rpy="0.0 0.0 0.0"/>
            <geometry>
                <box size="0.3 0.3 0.15"/>
            </geometry>
            <material name="blue">   
            </material>
        </collision>
    </link>



    <xacro:macro name="wheel_direction" params="name xyz">
    <joint name="joint_${name}" type="continuous">
        <origin rpy="0 1.57075 1.57075 " xyz="${xyz}"/>
        <parent link="chassis"/>
        <child link="joint_link_${name}"/>
        <axis xyz="0.0 0.0 1.0"/>
    </joint>

    <link name="joint_link_${name}">
        <inertial>
            <origin xyz="0.0 0.0 0.0" rpy="0.0 0.0 0.0"/>
            <mass value="0.1"/>
            <inertia ixx="8.334e-05" ixy="0.0" ixz="0.0" iyy="8.334e-05" iyz="0.0" izz="0.000125" />
        </inertial>
        <visual name="">
            <origin xyz="0.0 0.0 0.0" rpy="0.0 0.0 0.0"/>
            <geometry>
                <cylinder length="0.05" radius="0.05"/>
            </geometry>
            <material name="orange"/>
        </visual>
        <collision>
            <origin xyz="0.0 0.0 0.0" rpy="0.0 0.0 0.0"/>
            <geometry>
                <cylinder length="0.05" radius="0.05"/>
            </geometry>
        </collision>
    </link>
    </xacro:macro>

    <xacro:wheel_direction name="right" xyz = "0.06 0.175 0" />
    <xacro:wheel_direction name="left" xyz = "0.06 -0.175 0" />
    

    <joint name="joint_chaster" type="fixed">
        <origin xyz="0.24 0.0 0.0" rpy="0.0 0.0 0.0"/>
        <parent link="chassis"/>
        <child link="caster_wheel"/>
    </joint>
    
    
    
    
    <link name="caster_wheel">
        <inertial>
            <origin xyz="0.0 0.0 0.0" rpy="0.0 0.0 0.0"/>
            <mass value="0.010"/>
            <inertia ixx="0.00010" ixy="0.0" ixz="0.0" iyy="0.00010" iyz="0.0" izz="0.00010" />
        </inertial>
        <visual name="">
            <origin xyz="0.0 0.0 0.0" rpy="0.0 0.0 0.0"/>
            <geometry>
                <sphere radius="0.05" />
            </geometry>
            <material name="black"/>

        </visual>
        <collision>
            <origin xyz="0.0 0.0 0.0" rpy="0.0 0.0 0.0"/>
            <geometry>
                <sphere radius="0.05" />
            </geometry>
            <material name="black"/>
        </collision>
    </link>


    <joint name="joint_cam" type="fixed">
        <origin xyz="0.3 0.0 0.15" rpy="0.0 0.0 0.0"/>
        <parent link="chassis"/>
        <child link="camera_link"/>
        <axis xyz="0.0 0.0 0.0"/>
    </joint>

    <link name="camera_link">
        <inertial>
            <origin xyz="0.0 0.0 0.0" rpy="0.0 0.0 0.0"/>
            <mass value="0.0"/>
            <inertia ixx="0.0" ixy="0.0" ixz="0.0" iyy="0.0" iyz="0.0" izz="0.0"/>
        </inertial>
        <visual name="">
            <origin xyz="0.0 0.0 0.0" rpy="0.0 0.0 0.0"/>
            <geometry>
                <box size="0.05 0.05 0.05"/>
            </geometry>
            <material name="">
                <color rgba="1.0 0.0 0.0 1.0"/>
                <texture filename=""/>
            </material>
        </visual>
        <collision>
            <origin xyz="0.0 0.0 0.0" rpy="0.0 0.0 0.0"/>
            <geometry>
                <box size="0.05 0.05 0.05"/>
            </geometry>
        </collision>
    </link>

</robot>